[2024-06-06T14:15:27.547+0000] {taskinstance.py:1956} INFO - Dependencies all met for dep_context=non-requeueable deps ti=<TaskInstance: test_dag.test_rds_conn manual__2024-06-06T14:09:07.980442+00:00 [queued]>
[2024-06-06T14:15:27.550+0000] {taskinstance.py:1956} INFO - Dependencies all met for dep_context=requeueable deps ti=<TaskInstance: test_dag.test_rds_conn manual__2024-06-06T14:09:07.980442+00:00 [queued]>
[2024-06-06T14:15:27.551+0000] {taskinstance.py:2170} INFO - Starting attempt 2 of 2
[2024-06-06T14:15:27.555+0000] {taskinstance.py:2191} INFO - Executing <Task(PythonOperator): test_rds_conn> on 2024-06-06 14:09:07.980442+00:00
[2024-06-06T14:15:27.558+0000] {standard_task_runner.py:60} INFO - Started process 2148 to run task
[2024-06-06T14:15:27.559+0000] {standard_task_runner.py:87} INFO - Running: ['airflow', 'tasks', 'run', 'test_dag', 'test_rds_conn', 'manual__2024-06-06T14:09:07.980442+00:00', '--job-id', '31', '--raw', '--subdir', 'DAGS_FOLDER/test_airflow.py', '--cfg-path', '/tmp/tmp261poq88']
[2024-06-06T14:15:27.560+0000] {standard_task_runner.py:88} INFO - Job 31: Subtask test_rds_conn
[2024-06-06T14:15:27.566+0000] {logging_mixin.py:188} WARNING - /home/airflow/.local/lib/python3.9/site-packages/airflow/settings.py:194 DeprecationWarning: The sql_alchemy_conn option in [core] has been moved to the sql_alchemy_conn option in [database] - the old setting has been used, but please update your config.
[2024-06-06T14:15:27.579+0000] {task_command.py:423} INFO - Running <TaskInstance: test_dag.test_rds_conn manual__2024-06-06T14:09:07.980442+00:00 [running]> on host 83d825580a0b
[2024-06-06T14:15:27.610+0000] {taskinstance.py:2480} INFO - Exporting env vars: AIRFLOW_CTX_DAG_OWNER='johndoe' AIRFLOW_CTX_DAG_ID='test_dag' AIRFLOW_CTX_TASK_ID='test_rds_conn' AIRFLOW_CTX_EXECUTION_DATE='2024-06-06T14:09:07.980442+00:00' AIRFLOW_CTX_TRY_NUMBER='2' AIRFLOW_CTX_DAG_RUN_ID='manual__2024-06-06T14:09:07.980442+00:00'
[2024-06-06T14:16:42.637+0000] {logging_mixin.py:188} INFO - The error 'connection to server at "billyin-hw4-pub-acc-2.cvwhaidrmrqj.us-east-2.rds.amazonaws.com" (3.16.197.43), port 5432 failed: Connection refused
	Is the server running on that host and accepting TCP/IP connections?
' occurred
[2024-06-06T14:16:42.639+0000] {python.py:201} INFO - Done. Returned value was: None
[2024-06-06T14:16:42.662+0000] {taskinstance.py:1138} INFO - Marking task as SUCCESS. dag_id=test_dag, task_id=test_rds_conn, execution_date=20240606T140907, start_date=20240606T141527, end_date=20240606T141642
[2024-06-06T14:16:42.695+0000] {local_task_job_runner.py:234} INFO - Task exited with return code 0
[2024-06-06T14:16:42.710+0000] {taskinstance.py:3280} INFO - 0 downstream tasks scheduled from follow-on schedule check
