[2024-06-06T12:42:53.098+0000] {taskinstance.py:1956} INFO - Dependencies all met for dep_context=non-requeueable deps ti=<TaskInstance: p1_dag.initial_impute scheduled__2024-06-05T00:00:00+00:00 [queued]>
[2024-06-06T12:42:53.101+0000] {taskinstance.py:1956} INFO - Dependencies all met for dep_context=requeueable deps ti=<TaskInstance: p1_dag.initial_impute scheduled__2024-06-05T00:00:00+00:00 [queued]>
[2024-06-06T12:42:53.102+0000] {taskinstance.py:2170} INFO - Starting attempt 1 of 2
[2024-06-06T12:42:53.108+0000] {taskinstance.py:2191} INFO - Executing <Task(PythonOperator): initial_impute> on 2024-06-05 00:00:00+00:00
[2024-06-06T12:42:53.110+0000] {standard_task_runner.py:60} INFO - Started process 646 to run task
[2024-06-06T12:42:53.113+0000] {standard_task_runner.py:87} INFO - Running: ['airflow', 'tasks', 'run', 'p1_dag', 'initial_impute', 'scheduled__2024-06-05T00:00:00+00:00', '--job-id', '4', '--raw', '--subdir', 'DAGS_FOLDER/path1.py', '--cfg-path', '/tmp/tmp38xqtqrx']
[2024-06-06T12:42:53.113+0000] {standard_task_runner.py:88} INFO - Job 4: Subtask initial_impute
[2024-06-06T12:42:53.122+0000] {logging_mixin.py:188} WARNING - /home/airflow/.local/lib/python3.9/site-packages/airflow/settings.py:194 DeprecationWarning: The sql_alchemy_conn option in [core] has been moved to the sql_alchemy_conn option in [database] - the old setting has been used, but please update your config.
[2024-06-06T12:42:53.140+0000] {task_command.py:423} INFO - Running <TaskInstance: p1_dag.initial_impute scheduled__2024-06-05T00:00:00+00:00 [running]> on host da925791f65a
[2024-06-06T12:42:53.173+0000] {taskinstance.py:2480} INFO - Exporting env vars: AIRFLOW_CTX_DAG_OWNER='billyin' AIRFLOW_CTX_DAG_ID='p1_dag' AIRFLOW_CTX_TASK_ID='initial_impute' AIRFLOW_CTX_EXECUTION_DATE='2024-06-05T00:00:00+00:00' AIRFLOW_CTX_TRY_NUMBER='1' AIRFLOW_CTX_DAG_RUN_ID='scheduled__2024-06-05T00:00:00+00:00'
[2024-06-06T12:42:53.175+0000] {taskinstance.py:2698} ERROR - Task failed with exception
Traceback (most recent call last):
  File "/home/airflow/.local/lib/python3.9/site-packages/airflow/models/taskinstance.py", line 433, in _execute_task
    result = execute_callable(context=context, **execute_callable_kwargs)
  File "/home/airflow/.local/lib/python3.9/site-packages/airflow/operators/python.py", line 199, in execute
    return_value = self.execute_callable()
  File "/home/airflow/.local/lib/python3.9/site-packages/airflow/operators/python.py", line 216, in execute_callable
    return self.python_callable(*self.op_args, **self.op_kwargs)
TypeError: initial_impute() missing 1 required positional argument: 'data'
[2024-06-06T12:42:53.178+0000] {taskinstance.py:1138} INFO - Marking task as UP_FOR_RETRY. dag_id=p1_dag, task_id=initial_impute, execution_date=20240605T000000, start_date=20240606T124253, end_date=20240606T124253
[2024-06-06T12:42:53.182+0000] {standard_task_runner.py:107} ERROR - Failed to execute job 4 for task initial_impute (initial_impute() missing 1 required positional argument: 'data'; 646)
[2024-06-06T12:42:53.210+0000] {local_task_job_runner.py:234} INFO - Task exited with return code 1
[2024-06-06T12:42:53.218+0000] {taskinstance.py:3280} INFO - 0 downstream tasks scheduled from follow-on schedule check
[2024-06-06T13:17:49.832+0000] {taskinstance.py:1956} INFO - Dependencies all met for dep_context=non-requeueable deps ti=<TaskInstance: p1_dag.initial_impute scheduled__2024-06-05T00:00:00+00:00 [queued]>
[2024-06-06T13:17:49.837+0000] {taskinstance.py:1956} INFO - Dependencies all met for dep_context=requeueable deps ti=<TaskInstance: p1_dag.initial_impute scheduled__2024-06-05T00:00:00+00:00 [queued]>
[2024-06-06T13:17:49.837+0000] {taskinstance.py:2170} INFO - Starting attempt 1 of 2
[2024-06-06T13:17:49.844+0000] {taskinstance.py:2191} INFO - Executing <Task(PythonOperator): initial_impute> on 2024-06-05 00:00:00+00:00
[2024-06-06T13:17:49.849+0000] {standard_task_runner.py:60} INFO - Started process 182 to run task
[2024-06-06T13:17:49.851+0000] {standard_task_runner.py:87} INFO - Running: ['airflow', 'tasks', 'run', 'p1_dag', 'initial_impute', 'scheduled__2024-06-05T00:00:00+00:00', '--job-id', '2', '--raw', '--subdir', 'DAGS_FOLDER/path1.py', '--cfg-path', '/tmp/tmpsj1ln6e3']
[2024-06-06T13:17:49.855+0000] {standard_task_runner.py:88} INFO - Job 2: Subtask initial_impute
[2024-06-06T13:17:49.871+0000] {logging_mixin.py:188} WARNING - /home/airflow/.local/lib/python3.9/site-packages/airflow/settings.py:194 DeprecationWarning: The sql_alchemy_conn option in [core] has been moved to the sql_alchemy_conn option in [database] - the old setting has been used, but please update your config.
[2024-06-06T13:17:49.890+0000] {task_command.py:423} INFO - Running <TaskInstance: p1_dag.initial_impute scheduled__2024-06-05T00:00:00+00:00 [running]> on host 83d825580a0b
[2024-06-06T13:17:49.927+0000] {taskinstance.py:2480} INFO - Exporting env vars: AIRFLOW_CTX_DAG_OWNER='billyin' AIRFLOW_CTX_DAG_ID='p1_dag' AIRFLOW_CTX_TASK_ID='initial_impute' AIRFLOW_CTX_EXECUTION_DATE='2024-06-05T00:00:00+00:00' AIRFLOW_CTX_TRY_NUMBER='1' AIRFLOW_CTX_DAG_RUN_ID='scheduled__2024-06-05T00:00:00+00:00'
[2024-06-06T13:19:04.957+0000] {taskinstance.py:2698} ERROR - Task failed with exception
Traceback (most recent call last):
  File "/home/airflow/.local/lib/python3.9/site-packages/sqlalchemy/engine/base.py", line 3371, in _wrap_pool_connect
    return fn()
  File "/home/airflow/.local/lib/python3.9/site-packages/sqlalchemy/pool/base.py", line 327, in connect
    return _ConnectionFairy._checkout(self)
  File "/home/airflow/.local/lib/python3.9/site-packages/sqlalchemy/pool/base.py", line 894, in _checkout
    fairy = _ConnectionRecord.checkout(pool)
  File "/home/airflow/.local/lib/python3.9/site-packages/sqlalchemy/pool/base.py", line 493, in checkout
    rec = pool._do_get()
  File "/home/airflow/.local/lib/python3.9/site-packages/sqlalchemy/pool/impl.py", line 146, in _do_get
    self._dec_overflow()
  File "/home/airflow/.local/lib/python3.9/site-packages/sqlalchemy/util/langhelpers.py", line 70, in __exit__
    compat.raise_(
  File "/home/airflow/.local/lib/python3.9/site-packages/sqlalchemy/util/compat.py", line 211, in raise_
    raise exception
  File "/home/airflow/.local/lib/python3.9/site-packages/sqlalchemy/pool/impl.py", line 143, in _do_get
    return self._create_connection()
  File "/home/airflow/.local/lib/python3.9/site-packages/sqlalchemy/pool/base.py", line 273, in _create_connection
    return _ConnectionRecord(self)
  File "/home/airflow/.local/lib/python3.9/site-packages/sqlalchemy/pool/base.py", line 388, in __init__
    self.__connect()
  File "/home/airflow/.local/lib/python3.9/site-packages/sqlalchemy/pool/base.py", line 691, in __connect
    pool.logger.debug("Error on connect(): %s", e)
  File "/home/airflow/.local/lib/python3.9/site-packages/sqlalchemy/util/langhelpers.py", line 70, in __exit__
    compat.raise_(
  File "/home/airflow/.local/lib/python3.9/site-packages/sqlalchemy/util/compat.py", line 211, in raise_
    raise exception
  File "/home/airflow/.local/lib/python3.9/site-packages/sqlalchemy/pool/base.py", line 686, in __connect
    self.dbapi_connection = connection = pool._invoke_creator(self)
  File "/home/airflow/.local/lib/python3.9/site-packages/sqlalchemy/engine/create.py", line 574, in connect
    return dialect.connect(*cargs, **cparams)
  File "/home/airflow/.local/lib/python3.9/site-packages/sqlalchemy/engine/default.py", line 598, in connect
    return self.dbapi.connect(*cargs, **cparams)
  File "/home/airflow/.local/lib/python3.9/site-packages/psycopg2/__init__.py", line 122, in connect
    conn = _connect(dsn, connection_factory=connection_factory, **kwasync)
psycopg2.OperationalError: connection to server at "billyin-hw4-db.cvwhaidrmrqj.us-east-2.rds.amazonaws.com" (10.192.0.216), port 5432 failed: Connection refused
	Is the server running on that host and accepting TCP/IP connections?


The above exception was the direct cause of the following exception:

Traceback (most recent call last):
  File "/home/airflow/.local/lib/python3.9/site-packages/airflow/models/taskinstance.py", line 433, in _execute_task
    result = execute_callable(context=context, **execute_callable_kwargs)
  File "/home/airflow/.local/lib/python3.9/site-packages/airflow/operators/python.py", line 199, in execute
    return_value = self.execute_callable()
  File "/home/airflow/.local/lib/python3.9/site-packages/airflow/operators/python.py", line 216, in execute_callable
    return self.python_callable(*self.op_args, **self.op_kwargs)
  File "/opt/airflow/dags/path1.py", line 67, in wrapper
    conn = engine.connect()
  File "/home/airflow/.local/lib/python3.9/site-packages/sqlalchemy/engine/base.py", line 3325, in connect
    return self._connection_cls(self, close_with_result=close_with_result)
  File "/home/airflow/.local/lib/python3.9/site-packages/sqlalchemy/engine/base.py", line 96, in __init__
    else engine.raw_connection()
  File "/home/airflow/.local/lib/python3.9/site-packages/sqlalchemy/engine/base.py", line 3404, in raw_connection
    return self._wrap_pool_connect(self.pool.connect, _connection)
  File "/home/airflow/.local/lib/python3.9/site-packages/sqlalchemy/engine/base.py", line 3374, in _wrap_pool_connect
    Connection._handle_dbapi_exception_noconnection(
  File "/home/airflow/.local/lib/python3.9/site-packages/sqlalchemy/engine/base.py", line 2208, in _handle_dbapi_exception_noconnection
    util.raise_(
  File "/home/airflow/.local/lib/python3.9/site-packages/sqlalchemy/util/compat.py", line 211, in raise_
    raise exception
  File "/home/airflow/.local/lib/python3.9/site-packages/sqlalchemy/engine/base.py", line 3371, in _wrap_pool_connect
    return fn()
  File "/home/airflow/.local/lib/python3.9/site-packages/sqlalchemy/pool/base.py", line 327, in connect
    return _ConnectionFairy._checkout(self)
  File "/home/airflow/.local/lib/python3.9/site-packages/sqlalchemy/pool/base.py", line 894, in _checkout
    fairy = _ConnectionRecord.checkout(pool)
  File "/home/airflow/.local/lib/python3.9/site-packages/sqlalchemy/pool/base.py", line 493, in checkout
    rec = pool._do_get()
  File "/home/airflow/.local/lib/python3.9/site-packages/sqlalchemy/pool/impl.py", line 146, in _do_get
    self._dec_overflow()
  File "/home/airflow/.local/lib/python3.9/site-packages/sqlalchemy/util/langhelpers.py", line 70, in __exit__
    compat.raise_(
  File "/home/airflow/.local/lib/python3.9/site-packages/sqlalchemy/util/compat.py", line 211, in raise_
    raise exception
  File "/home/airflow/.local/lib/python3.9/site-packages/sqlalchemy/pool/impl.py", line 143, in _do_get
    return self._create_connection()
  File "/home/airflow/.local/lib/python3.9/site-packages/sqlalchemy/pool/base.py", line 273, in _create_connection
    return _ConnectionRecord(self)
  File "/home/airflow/.local/lib/python3.9/site-packages/sqlalchemy/pool/base.py", line 388, in __init__
    self.__connect()
  File "/home/airflow/.local/lib/python3.9/site-packages/sqlalchemy/pool/base.py", line 691, in __connect
    pool.logger.debug("Error on connect(): %s", e)
  File "/home/airflow/.local/lib/python3.9/site-packages/sqlalchemy/util/langhelpers.py", line 70, in __exit__
    compat.raise_(
  File "/home/airflow/.local/lib/python3.9/site-packages/sqlalchemy/util/compat.py", line 211, in raise_
    raise exception
  File "/home/airflow/.local/lib/python3.9/site-packages/sqlalchemy/pool/base.py", line 686, in __connect
    self.dbapi_connection = connection = pool._invoke_creator(self)
  File "/home/airflow/.local/lib/python3.9/site-packages/sqlalchemy/engine/create.py", line 574, in connect
    return dialect.connect(*cargs, **cparams)
  File "/home/airflow/.local/lib/python3.9/site-packages/sqlalchemy/engine/default.py", line 598, in connect
    return self.dbapi.connect(*cargs, **cparams)
  File "/home/airflow/.local/lib/python3.9/site-packages/psycopg2/__init__.py", line 122, in connect
    conn = _connect(dsn, connection_factory=connection_factory, **kwasync)
sqlalchemy.exc.OperationalError: (psycopg2.OperationalError) connection to server at "billyin-hw4-db.cvwhaidrmrqj.us-east-2.rds.amazonaws.com" (10.192.0.216), port 5432 failed: Connection refused
	Is the server running on that host and accepting TCP/IP connections?

(Background on this error at: https://sqlalche.me/e/14/e3q8)
[2024-06-06T13:19:04.972+0000] {taskinstance.py:1138} INFO - Marking task as UP_FOR_RETRY. dag_id=p1_dag, task_id=initial_impute, execution_date=20240605T000000, start_date=20240606T131749, end_date=20240606T131904
[2024-06-06T13:19:04.982+0000] {standard_task_runner.py:107} ERROR - Failed to execute job 2 for task initial_impute ((psycopg2.OperationalError) connection to server at "billyin-hw4-db.cvwhaidrmrqj.us-east-2.rds.amazonaws.com" (10.192.0.216), port 5432 failed: Connection refused
	Is the server running on that host and accepting TCP/IP connections?

(Background on this error at: https://sqlalche.me/e/14/e3q8); 182)
[2024-06-06T13:19:05.005+0000] {local_task_job_runner.py:234} INFO - Task exited with return code 1
[2024-06-06T13:19:05.016+0000] {taskinstance.py:3280} INFO - 0 downstream tasks scheduled from follow-on schedule check
